Traceback (most recent call last):
  File "/data/lily/hh638/Health/simplification-project/gpt.py", line 1, in <module>
    import openai
ModuleNotFoundError: No module named 'openai'
Using custom data configuration default-c5ed1eb5cd46c292
Downloading and preparing dataset json/default to /home/lily/hh638/.cache/huggingface/datasets/json/default-c5ed1eb5cd46c292/0.0.0/ac0ca5f5289a6cf108e706efcf040422dbbfa8e658dee6a819f20d76bb84d26b...
Downloading data files:   0%|          | 0/1 [00:00<?, ?it/s]Downloading data files: 100%|██████████| 1/1 [00:00<00:00, 2313.46it/s]
Extracting data files:   0%|          | 0/1 [00:00<?, ?it/s]Extracting data files: 100%|██████████| 1/1 [00:00<00:00, 267.24it/s]
Dataset json downloaded and prepared to /home/lily/hh638/.cache/huggingface/datasets/json/default-c5ed1eb5cd46c292/0.0.0/ac0ca5f5289a6cf108e706efcf040422dbbfa8e658dee6a819f20d76bb84d26b. Subsequent calls will reuse this data.
  0%|          | 0/1 [00:00<?, ?it/s]100%|██████████| 1/1 [00:00<00:00, 48.61it/s]
turkcorpus_context_all Done
Using custom data configuration default-5eccd33a13ccd331
Downloading and preparing dataset json/default to /home/lily/hh638/.cache/huggingface/datasets/json/default-5eccd33a13ccd331/0.0.0/ac0ca5f5289a6cf108e706efcf040422dbbfa8e658dee6a819f20d76bb84d26b...
Downloading data files:   0%|          | 0/1 [00:00<?, ?it/s]Downloading data files: 100%|██████████| 1/1 [00:00<00:00, 6141.00it/s]
Extracting data files:   0%|          | 0/1 [00:00<?, ?it/s]Extracting data files: 100%|██████████| 1/1 [00:00<00:00, 267.12it/s]
Dataset json downloaded and prepared to /home/lily/hh638/.cache/huggingface/datasets/json/default-5eccd33a13ccd331/0.0.0/ac0ca5f5289a6cf108e706efcf040422dbbfa8e658dee6a819f20d76bb84d26b. Subsequent calls will reuse this data.
  0%|          | 0/1 [00:00<?, ?it/s]100%|██████████| 1/1 [00:00<00:00, 296.84it/s]
Traceback (most recent call last):
  File "gpt.py", line 23, in <module>
    response = openai.ChatCompletion.create(
  File "/home/lily/hh638/anaconda3/envs/simplification/lib/python3.8/site-packages/openai/api_resources/chat_completion.py", line 25, in create
    return super().create(*args, **kwargs)
  File "/home/lily/hh638/anaconda3/envs/simplification/lib/python3.8/site-packages/openai/api_resources/abstract/engine_api_resource.py", line 153, in create
    response, _, api_key = requestor.request(
  File "/home/lily/hh638/anaconda3/envs/simplification/lib/python3.8/site-packages/openai/api_requestor.py", line 226, in request
    resp, got_stream = self._interpret_response(result, stream)
  File "/home/lily/hh638/anaconda3/envs/simplification/lib/python3.8/site-packages/openai/api_requestor.py", line 620, in _interpret_response
    self._interpret_response_line(
  File "/home/lily/hh638/anaconda3/envs/simplification/lib/python3.8/site-packages/openai/api_requestor.py", line 683, in _interpret_response_line
    raise self.handle_error_response(
openai.error.APIError: Bad gateway. {"error":{"code":502,"message":"Bad gateway.","param":null,"type":"cf_bad_gateway"}} 502 {'error': {'code': 502, 'message': 'Bad gateway.', 'param': None, 'type': 'cf_bad_gateway'}} {'Date': 'Mon, 24 Apr 2023 20:13:01 GMT', 'Content-Type': 'application/json', 'Content-Length': '84', 'Connection': 'keep-alive', 'X-Frame-Options': 'SAMEORIGIN', 'Referrer-Policy': 'same-origin', 'Cache-Control': 'private, max-age=0, no-store, no-cache, must-revalidate, post-check=0, pre-check=0', 'Expires': 'Thu, 01 Jan 1970 00:00:01 GMT', 'Server': 'cloudflare', 'CF-RAY': '7bd0f9768c020f3b-EWR'}
Traceback (most recent call last):
  File "/data/lily/hh638/Health/simplification-project/gpt.py", line 1, in <module>
    import openai
ModuleNotFoundError: No module named 'openai'
Using custom data configuration default-5eccd33a13ccd331
Reusing dataset json (/home/lily/hh638/.cache/huggingface/datasets/json/default-5eccd33a13ccd331/0.0.0/ac0ca5f5289a6cf108e706efcf040422dbbfa8e658dee6a819f20d76bb84d26b)
  0%|          | 0/1 [00:00<?, ?it/s]100%|██████████| 1/1 [00:00<00:00, 20.87it/s]
