Using custom data configuration default-3f91e594c1b18797
Reusing dataset json (/home/lily/hh638/.cache/huggingface/datasets/json/default-3f91e594c1b18797/0.0.0/ac0ca5f5289a6cf108e706efcf040422dbbfa8e658dee6a819f20d76bb84d26b)
  0%|          | 0/1 [00:00<?, ?it/s]100%|██████████| 1/1 [00:00<00:00,  6.55it/s]100%|██████████| 1/1 [00:00<00:00,  6.53it/s]
Traceback (most recent call last):
  File "gpt.py", line 22, in <module>
    response = openai.ChatCompletion.create(
  File "/home/lily/hh638/anaconda3/envs/simplification/lib/python3.8/site-packages/openai/api_resources/chat_completion.py", line 25, in create
    return super().create(*args, **kwargs)
  File "/home/lily/hh638/anaconda3/envs/simplification/lib/python3.8/site-packages/openai/api_resources/abstract/engine_api_resource.py", line 153, in create
    response, _, api_key = requestor.request(
  File "/home/lily/hh638/anaconda3/envs/simplification/lib/python3.8/site-packages/openai/api_requestor.py", line 226, in request
    resp, got_stream = self._interpret_response(result, stream)
  File "/home/lily/hh638/anaconda3/envs/simplification/lib/python3.8/site-packages/openai/api_requestor.py", line 620, in _interpret_response
    self._interpret_response_line(
  File "/home/lily/hh638/anaconda3/envs/simplification/lib/python3.8/site-packages/openai/api_requestor.py", line 683, in _interpret_response_line
    raise self.handle_error_response(
openai.error.APIError: Gateway timeout. {"error":{"code":524,"message":"Gateway timeout.","param":null,"type":"cf_gateway_timeout"}} 524 {'error': {'code': 524, 'message': 'Gateway timeout.', 'param': None, 'type': 'cf_gateway_timeout'}} {'Date': 'Sat, 22 Apr 2023 20:31:31 GMT', 'Content-Type': 'application/json', 'Content-Length': '92', 'Connection': 'keep-alive', 'X-Frame-Options': 'SAMEORIGIN', 'Referrer-Policy': 'same-origin', 'Cache-Control': 'private, max-age=0, no-store, no-cache, must-revalidate, post-check=0, pre-check=0', 'Expires': 'Thu, 01 Jan 1970 00:00:01 GMT', 'Server': 'cloudflare', 'CF-RAY': '7bc092d659ac8c2a-EWR'}
Using custom data configuration default-3f91e594c1b18797
Reusing dataset json (/home/lily/hh638/.cache/huggingface/datasets/json/default-3f91e594c1b18797/0.0.0/ac0ca5f5289a6cf108e706efcf040422dbbfa8e658dee6a819f20d76bb84d26b)
  0%|          | 0/1 [00:00<?, ?it/s]100%|██████████| 1/1 [00:00<00:00, 346.41it/s]
Traceback (most recent call last):
  File "gpt.py", line 22, in <module>
    response = openai.ChatCompletion.create(
  File "/home/lily/hh638/anaconda3/envs/simplification/lib/python3.8/site-packages/openai/api_resources/chat_completion.py", line 25, in create
    return super().create(*args, **kwargs)
  File "/home/lily/hh638/anaconda3/envs/simplification/lib/python3.8/site-packages/openai/api_resources/abstract/engine_api_resource.py", line 153, in create
    response, _, api_key = requestor.request(
  File "/home/lily/hh638/anaconda3/envs/simplification/lib/python3.8/site-packages/openai/api_requestor.py", line 226, in request
    resp, got_stream = self._interpret_response(result, stream)
  File "/home/lily/hh638/anaconda3/envs/simplification/lib/python3.8/site-packages/openai/api_requestor.py", line 620, in _interpret_response
    self._interpret_response_line(
  File "/home/lily/hh638/anaconda3/envs/simplification/lib/python3.8/site-packages/openai/api_requestor.py", line 683, in _interpret_response_line
    raise self.handle_error_response(
openai.error.APIError: Bad gateway. {"error":{"code":502,"message":"Bad gateway.","param":null,"type":"cf_bad_gateway"}} 502 {'error': {'code': 502, 'message': 'Bad gateway.', 'param': None, 'type': 'cf_bad_gateway'}} {'Date': 'Sat, 22 Apr 2023 20:50:01 GMT', 'Content-Type': 'application/json', 'Content-Length': '84', 'Connection': 'keep-alive', 'X-Frame-Options': 'SAMEORIGIN', 'Referrer-Policy': 'same-origin', 'Cache-Control': 'private, max-age=0, no-store, no-cache, must-revalidate, post-check=0, pre-check=0', 'Expires': 'Thu, 01 Jan 1970 00:00:01 GMT', 'Server': 'cloudflare', 'CF-RAY': '7bc0b4f92f154384-EWR'}
Using custom data configuration default-3f91e594c1b18797
Reusing dataset json (/home/lily/hh638/.cache/huggingface/datasets/json/default-3f91e594c1b18797/0.0.0/ac0ca5f5289a6cf108e706efcf040422dbbfa8e658dee6a819f20d76bb84d26b)
  0%|          | 0/1 [00:00<?, ?it/s]100%|██████████| 1/1 [00:00<00:00, 364.47it/s]
asset Done
Using custom data configuration default-3e04eaeca4c47c7c
Reusing dataset json (/home/lily/hh638/.cache/huggingface/datasets/json/default-3e04eaeca4c47c7c/0.0.0/ac0ca5f5289a6cf108e706efcf040422dbbfa8e658dee6a819f20d76bb84d26b)
  0%|          | 0/1 [00:00<?, ?it/s]100%|██████████| 1/1 [00:00<00:00, 22.34it/s]
Traceback (most recent call last):
  File "gpt.py", line 22, in <module>
    response = openai.ChatCompletion.create(
  File "/home/lily/hh638/anaconda3/envs/simplification/lib/python3.8/site-packages/openai/api_resources/chat_completion.py", line 25, in create
    return super().create(*args, **kwargs)
  File "/home/lily/hh638/anaconda3/envs/simplification/lib/python3.8/site-packages/openai/api_resources/abstract/engine_api_resource.py", line 153, in create
    response, _, api_key = requestor.request(
  File "/home/lily/hh638/anaconda3/envs/simplification/lib/python3.8/site-packages/openai/api_requestor.py", line 226, in request
    resp, got_stream = self._interpret_response(result, stream)
  File "/home/lily/hh638/anaconda3/envs/simplification/lib/python3.8/site-packages/openai/api_requestor.py", line 620, in _interpret_response
    self._interpret_response_line(
  File "/home/lily/hh638/anaconda3/envs/simplification/lib/python3.8/site-packages/openai/api_requestor.py", line 683, in _interpret_response_line
    raise self.handle_error_response(
openai.error.APIError: Bad gateway. {"error":{"code":502,"message":"Bad gateway.","param":null,"type":"cf_bad_gateway"}} 502 {'error': {'code': 502, 'message': 'Bad gateway.', 'param': None, 'type': 'cf_bad_gateway'}} {'Date': 'Sat, 22 Apr 2023 23:20:41 GMT', 'Content-Type': 'application/json', 'Content-Length': '84', 'Connection': 'keep-alive', 'X-Frame-Options': 'SAMEORIGIN', 'Referrer-Policy': 'same-origin', 'Cache-Control': 'private, max-age=0, no-store, no-cache, must-revalidate, post-check=0, pre-check=0', 'Expires': 'Thu, 01 Jan 1970 00:00:01 GMT', 'Server': 'cloudflare', 'CF-RAY': '7bc19165cfd4c32e-EWR'}
Using custom data configuration default-e55755119d653c8e
Reusing dataset json (/home/lily/hh638/.cache/huggingface/datasets/json/default-e55755119d653c8e/0.0.0/ac0ca5f5289a6cf108e706efcf040422dbbfa8e658dee6a819f20d76bb84d26b)
  0%|          | 0/1 [00:00<?, ?it/s]100%|██████████| 1/1 [00:00<00:00, 23.70it/s]
Traceback (most recent call last):
  File "gpt.py", line 22, in <module>
    response = openai.ChatCompletion.create(
  File "/home/lily/hh638/anaconda3/envs/simplification/lib/python3.8/site-packages/openai/api_resources/chat_completion.py", line 25, in create
    return super().create(*args, **kwargs)
  File "/home/lily/hh638/anaconda3/envs/simplification/lib/python3.8/site-packages/openai/api_resources/abstract/engine_api_resource.py", line 153, in create
    response, _, api_key = requestor.request(
  File "/home/lily/hh638/anaconda3/envs/simplification/lib/python3.8/site-packages/openai/api_requestor.py", line 226, in request
    resp, got_stream = self._interpret_response(result, stream)
  File "/home/lily/hh638/anaconda3/envs/simplification/lib/python3.8/site-packages/openai/api_requestor.py", line 620, in _interpret_response
    self._interpret_response_line(
  File "/home/lily/hh638/anaconda3/envs/simplification/lib/python3.8/site-packages/openai/api_requestor.py", line 683, in _interpret_response_line
    raise self.handle_error_response(
openai.error.APIError: Bad gateway. {"error":{"code":502,"message":"Bad gateway.","param":null,"type":"cf_bad_gateway"}} 502 {'error': {'code': 502, 'message': 'Bad gateway.', 'param': None, 'type': 'cf_bad_gateway'}} {'Date': 'Sat, 22 Apr 2023 23:54:17 GMT', 'Content-Type': 'application/json', 'Content-Length': '84', 'Connection': 'keep-alive', 'X-Frame-Options': 'SAMEORIGIN', 'Referrer-Policy': 'same-origin', 'Cache-Control': 'private, max-age=0, no-store, no-cache, must-revalidate, post-check=0, pre-check=0', 'Expires': 'Thu, 01 Jan 1970 00:00:01 GMT', 'Server': 'cloudflare', 'CF-RAY': '7bc1c2d20d35c411-EWR'}
Using custom data configuration default-e55755119d653c8e
Reusing dataset json (/home/lily/hh638/.cache/huggingface/datasets/json/default-e55755119d653c8e/0.0.0/ac0ca5f5289a6cf108e706efcf040422dbbfa8e658dee6a819f20d76bb84d26b)
  0%|          | 0/1 [00:00<?, ?it/s]100%|██████████| 1/1 [00:00<00:00, 304.09it/s]
radiology_indiv Done
Using custom data configuration default-06084af75ccc14fc
Reusing dataset json (/home/lily/hh638/.cache/huggingface/datasets/json/default-06084af75ccc14fc/0.0.0/ac0ca5f5289a6cf108e706efcf040422dbbfa8e658dee6a819f20d76bb84d26b)
  0%|          | 0/1 [00:00<?, ?it/s]100%|██████████| 1/1 [00:00<00:00, 14.20it/s]
turkcorpus Done
Using custom data configuration default-06084af75ccc14fc
Reusing dataset json (/home/lily/hh638/.cache/huggingface/datasets/json/default-06084af75ccc14fc/0.0.0/ac0ca5f5289a6cf108e706efcf040422dbbfa8e658dee6a819f20d76bb84d26b)
  0%|          | 0/1 [00:00<?, ?it/s]100%|██████████| 1/1 [00:00<00:00, 346.41it/s]
Traceback (most recent call last):
  File "gpt.py", line 22, in <module>
    response = openai.ChatCompletion.create(
  File "/home/lily/hh638/anaconda3/envs/simplification/lib/python3.8/site-packages/openai/api_resources/chat_completion.py", line 25, in create
    return super().create(*args, **kwargs)
  File "/home/lily/hh638/anaconda3/envs/simplification/lib/python3.8/site-packages/openai/api_resources/abstract/engine_api_resource.py", line 153, in create
    response, _, api_key = requestor.request(
  File "/home/lily/hh638/anaconda3/envs/simplification/lib/python3.8/site-packages/openai/api_requestor.py", line 226, in request
    resp, got_stream = self._interpret_response(result, stream)
  File "/home/lily/hh638/anaconda3/envs/simplification/lib/python3.8/site-packages/openai/api_requestor.py", line 620, in _interpret_response
    self._interpret_response_line(
  File "/home/lily/hh638/anaconda3/envs/simplification/lib/python3.8/site-packages/openai/api_requestor.py", line 683, in _interpret_response_line
    raise self.handle_error_response(
openai.error.APIError: Bad gateway. {"error":{"code":502,"message":"Bad gateway.","param":null,"type":"cf_bad_gateway"}} 502 {'error': {'code': 502, 'message': 'Bad gateway.', 'param': None, 'type': 'cf_bad_gateway'}} {'Date': 'Sun, 23 Apr 2023 02:59:42 GMT', 'Content-Type': 'application/json', 'Content-Length': '84', 'Connection': 'keep-alive', 'X-Frame-Options': 'SAMEORIGIN', 'Referrer-Policy': 'same-origin', 'Cache-Control': 'private, max-age=0, no-store, no-cache, must-revalidate, post-check=0, pre-check=0', 'Expires': 'Thu, 01 Jan 1970 00:00:01 GMT', 'Server': 'cloudflare', 'CF-RAY': '7bc2d274c97c42a7-EWR'}
Using custom data configuration default-3e04eaeca4c47c7c
Reusing dataset json (/home/lily/hh638/.cache/huggingface/datasets/json/default-3e04eaeca4c47c7c/0.0.0/ac0ca5f5289a6cf108e706efcf040422dbbfa8e658dee6a819f20d76bb84d26b)
  0%|          | 0/1 [00:00<?, ?it/s]100%|██████████| 1/1 [00:00<00:00, 152.58it/s]
cochrane Done
Using custom data configuration default-e55755119d653c8e
Reusing dataset json (/home/lily/hh638/.cache/huggingface/datasets/json/default-e55755119d653c8e/0.0.0/ac0ca5f5289a6cf108e706efcf040422dbbfa8e658dee6a819f20d76bb84d26b)
  0%|          | 0/1 [00:00<?, ?it/s]100%|██████████| 1/1 [00:00<00:00, 34.78it/s]
Traceback (most recent call last):
  File "gpt.py", line 22, in <module>
    response = openai.ChatCompletion.create(
  File "/home/lily/hh638/anaconda3/envs/simplification/lib/python3.8/site-packages/openai/api_resources/chat_completion.py", line 25, in create
    return super().create(*args, **kwargs)
  File "/home/lily/hh638/anaconda3/envs/simplification/lib/python3.8/site-packages/openai/api_resources/abstract/engine_api_resource.py", line 153, in create
    response, _, api_key = requestor.request(
  File "/home/lily/hh638/anaconda3/envs/simplification/lib/python3.8/site-packages/openai/api_requestor.py", line 226, in request
    resp, got_stream = self._interpret_response(result, stream)
  File "/home/lily/hh638/anaconda3/envs/simplification/lib/python3.8/site-packages/openai/api_requestor.py", line 620, in _interpret_response
    self._interpret_response_line(
  File "/home/lily/hh638/anaconda3/envs/simplification/lib/python3.8/site-packages/openai/api_requestor.py", line 683, in _interpret_response_line
    raise self.handle_error_response(
openai.error.APIError: Bad gateway. {"error":{"code":502,"message":"Bad gateway.","param":null,"type":"cf_bad_gateway"}} 502 {'error': {'code': 502, 'message': 'Bad gateway.', 'param': None, 'type': 'cf_bad_gateway'}} {'Date': 'Sun, 23 Apr 2023 06:12:30 GMT', 'Content-Type': 'application/json', 'Content-Length': '84', 'Connection': 'keep-alive', 'X-Frame-Options': 'SAMEORIGIN', 'Referrer-Policy': 'same-origin', 'Cache-Control': 'private, max-age=0, no-store, no-cache, must-revalidate, post-check=0, pre-check=0', 'Expires': 'Thu, 01 Jan 1970 00:00:01 GMT', 'Server': 'cloudflare', 'CF-RAY': '7bc3f474de76181d-EWR'}
Using custom data configuration default-e55755119d653c8e
Reusing dataset json (/home/lily/hh638/.cache/huggingface/datasets/json/default-e55755119d653c8e/0.0.0/ac0ca5f5289a6cf108e706efcf040422dbbfa8e658dee6a819f20d76bb84d26b)
  0%|          | 0/1 [00:00<?, ?it/s]100%|██████████| 1/1 [00:00<00:00, 33.33it/s]
radiology_indiv Done
Using custom data configuration default-3e04eaeca4c47c7c
Reusing dataset json (/home/lily/hh638/.cache/huggingface/datasets/json/default-3e04eaeca4c47c7c/0.0.0/ac0ca5f5289a6cf108e706efcf040422dbbfa8e658dee6a819f20d76bb84d26b)
  0%|          | 0/1 [00:00<?, ?it/s]100%|██████████| 1/1 [00:00<00:00, 17.44it/s]
Traceback (most recent call last):
  File "gpt.py", line 22, in <module>
    response = openai.ChatCompletion.create(
  File "/home/lily/hh638/anaconda3/envs/simplification/lib/python3.8/site-packages/openai/api_resources/chat_completion.py", line 25, in create
    return super().create(*args, **kwargs)
  File "/home/lily/hh638/anaconda3/envs/simplification/lib/python3.8/site-packages/openai/api_resources/abstract/engine_api_resource.py", line 153, in create
    response, _, api_key = requestor.request(
  File "/home/lily/hh638/anaconda3/envs/simplification/lib/python3.8/site-packages/openai/api_requestor.py", line 226, in request
    resp, got_stream = self._interpret_response(result, stream)
  File "/home/lily/hh638/anaconda3/envs/simplification/lib/python3.8/site-packages/openai/api_requestor.py", line 620, in _interpret_response
    self._interpret_response_line(
  File "/home/lily/hh638/anaconda3/envs/simplification/lib/python3.8/site-packages/openai/api_requestor.py", line 683, in _interpret_response_line
    raise self.handle_error_response(
openai.error.APIError: Bad gateway. {"error":{"code":502,"message":"Bad gateway.","param":null,"type":"cf_bad_gateway"}} 502 {'error': {'code': 502, 'message': 'Bad gateway.', 'param': None, 'type': 'cf_bad_gateway'}} {'Date': 'Sun, 23 Apr 2023 17:08:06 GMT', 'Content-Type': 'application/json', 'Content-Length': '84', 'Connection': 'keep-alive', 'X-Frame-Options': 'SAMEORIGIN', 'Referrer-Policy': 'same-origin', 'Cache-Control': 'private, max-age=0, no-store, no-cache, must-revalidate, post-check=0, pre-check=0', 'Expires': 'Thu, 01 Jan 1970 00:00:01 GMT', 'Server': 'cloudflare', 'CF-RAY': '7bc7acd6cd914297-EWR'}
Using custom data configuration default-3e04eaeca4c47c7c
Reusing dataset json (/home/lily/hh638/.cache/huggingface/datasets/json/default-3e04eaeca4c47c7c/0.0.0/ac0ca5f5289a6cf108e706efcf040422dbbfa8e658dee6a819f20d76bb84d26b)
  0%|          | 0/1 [00:00<?, ?it/s]100%|██████████| 1/1 [00:00<00:00, 26.15it/s]
Traceback (most recent call last):
  File "gpt.py", line 22, in <module>
    response = openai.ChatCompletion.create(
  File "/home/lily/hh638/anaconda3/envs/simplification/lib/python3.8/site-packages/openai/api_resources/chat_completion.py", line 25, in create
    return super().create(*args, **kwargs)
  File "/home/lily/hh638/anaconda3/envs/simplification/lib/python3.8/site-packages/openai/api_resources/abstract/engine_api_resource.py", line 153, in create
    response, _, api_key = requestor.request(
  File "/home/lily/hh638/anaconda3/envs/simplification/lib/python3.8/site-packages/openai/api_requestor.py", line 226, in request
    resp, got_stream = self._interpret_response(result, stream)
  File "/home/lily/hh638/anaconda3/envs/simplification/lib/python3.8/site-packages/openai/api_requestor.py", line 620, in _interpret_response
    self._interpret_response_line(
  File "/home/lily/hh638/anaconda3/envs/simplification/lib/python3.8/site-packages/openai/api_requestor.py", line 683, in _interpret_response_line
    raise self.handle_error_response(
openai.error.APIError: Bad gateway. {"error":{"code":502,"message":"Bad gateway.","param":null,"type":"cf_bad_gateway"}} 502 {'error': {'code': 502, 'message': 'Bad gateway.', 'param': None, 'type': 'cf_bad_gateway'}} {'Date': 'Sun, 23 Apr 2023 18:52:04 GMT', 'Content-Type': 'application/json', 'Content-Length': '84', 'Connection': 'keep-alive', 'X-Frame-Options': 'SAMEORIGIN', 'Referrer-Policy': 'same-origin', 'Cache-Control': 'private, max-age=0, no-store, no-cache, must-revalidate, post-check=0, pre-check=0', 'Expires': 'Thu, 01 Jan 1970 00:00:01 GMT', 'Server': 'cloudflare', 'CF-RAY': '7bc845287ed14270-EWR'}
Using custom data configuration default-3f91e594c1b18797
Reusing dataset json (/home/lily/hh638/.cache/huggingface/datasets/json/default-3f91e594c1b18797/0.0.0/ac0ca5f5289a6cf108e706efcf040422dbbfa8e658dee6a819f20d76bb84d26b)
  0%|          | 0/1 [00:00<?, ?it/s]100%|██████████| 1/1 [00:00<00:00, 144.04it/s]
Traceback (most recent call last):
  File "gpt.py", line 22, in <module>
    response = openai.ChatCompletion.create(
  File "/home/lily/hh638/anaconda3/envs/simplification/lib/python3.8/site-packages/openai/api_resources/chat_completion.py", line 25, in create
    return super().create(*args, **kwargs)
  File "/home/lily/hh638/anaconda3/envs/simplification/lib/python3.8/site-packages/openai/api_resources/abstract/engine_api_resource.py", line 153, in create
    response, _, api_key = requestor.request(
  File "/home/lily/hh638/anaconda3/envs/simplification/lib/python3.8/site-packages/openai/api_requestor.py", line 226, in request
    resp, got_stream = self._interpret_response(result, stream)
  File "/home/lily/hh638/anaconda3/envs/simplification/lib/python3.8/site-packages/openai/api_requestor.py", line 620, in _interpret_response
    self._interpret_response_line(
  File "/home/lily/hh638/anaconda3/envs/simplification/lib/python3.8/site-packages/openai/api_requestor.py", line 683, in _interpret_response_line
    raise self.handle_error_response(
openai.error.APIError: Bad gateway. {"error":{"code":502,"message":"Bad gateway.","param":null,"type":"cf_bad_gateway"}} 502 {'error': {'code': 502, 'message': 'Bad gateway.', 'param': None, 'type': 'cf_bad_gateway'}} {'Date': 'Sun, 23 Apr 2023 19:18:24 GMT', 'Content-Type': 'application/json', 'Content-Length': '84', 'Connection': 'keep-alive', 'X-Frame-Options': 'SAMEORIGIN', 'Referrer-Policy': 'same-origin', 'Cache-Control': 'private, max-age=0, no-store, no-cache, must-revalidate, post-check=0, pre-check=0', 'Expires': 'Thu, 01 Jan 1970 00:00:01 GMT', 'Server': 'cloudflare', 'CF-RAY': '7bc86c0dcb9c43e6-EWR'}
Using custom data configuration default-3f91e594c1b18797
Reusing dataset json (/home/lily/hh638/.cache/huggingface/datasets/json/default-3f91e594c1b18797/0.0.0/ac0ca5f5289a6cf108e706efcf040422dbbfa8e658dee6a819f20d76bb84d26b)
  0%|          | 0/1 [00:00<?, ?it/s]100%|██████████| 1/1 [00:00<00:00, 79.64it/s]
Traceback (most recent call last):
  File "gpt.py", line 22, in <module>
    response = openai.ChatCompletion.create(
  File "/home/lily/hh638/anaconda3/envs/simplification/lib/python3.8/site-packages/openai/api_resources/chat_completion.py", line 25, in create
    return super().create(*args, **kwargs)
  File "/home/lily/hh638/anaconda3/envs/simplification/lib/python3.8/site-packages/openai/api_resources/abstract/engine_api_resource.py", line 153, in create
    response, _, api_key = requestor.request(
  File "/home/lily/hh638/anaconda3/envs/simplification/lib/python3.8/site-packages/openai/api_requestor.py", line 226, in request
    resp, got_stream = self._interpret_response(result, stream)
  File "/home/lily/hh638/anaconda3/envs/simplification/lib/python3.8/site-packages/openai/api_requestor.py", line 620, in _interpret_response
    self._interpret_response_line(
  File "/home/lily/hh638/anaconda3/envs/simplification/lib/python3.8/site-packages/openai/api_requestor.py", line 683, in _interpret_response_line
    raise self.handle_error_response(
openai.error.APIError: Bad gateway. {"error":{"code":502,"message":"Bad gateway.","param":null,"type":"cf_bad_gateway"}} 502 {'error': {'code': 502, 'message': 'Bad gateway.', 'param': None, 'type': 'cf_bad_gateway'}} {'Date': 'Sun, 23 Apr 2023 19:54:26 GMT', 'Content-Type': 'application/json', 'Content-Length': '84', 'Connection': 'keep-alive', 'X-Frame-Options': 'SAMEORIGIN', 'Referrer-Policy': 'same-origin', 'Cache-Control': 'private, max-age=0, no-store, no-cache, must-revalidate, post-check=0, pre-check=0', 'Expires': 'Thu, 01 Jan 1970 00:00:01 GMT', 'Server': 'cloudflare', 'CF-RAY': '7bc8a0ddac594246-EWR'}
Using custom data configuration default-3f91e594c1b18797
Reusing dataset json (/home/lily/hh638/.cache/huggingface/datasets/json/default-3f91e594c1b18797/0.0.0/ac0ca5f5289a6cf108e706efcf040422dbbfa8e658dee6a819f20d76bb84d26b)
  0%|          | 0/1 [00:00<?, ?it/s]100%|██████████| 1/1 [00:00<00:00, 39.61it/s]
Traceback (most recent call last):
  File "gpt.py", line 22, in <module>
    response = openai.ChatCompletion.create(
  File "/home/lily/hh638/anaconda3/envs/simplification/lib/python3.8/site-packages/openai/api_resources/chat_completion.py", line 25, in create
    return super().create(*args, **kwargs)
  File "/home/lily/hh638/anaconda3/envs/simplification/lib/python3.8/site-packages/openai/api_resources/abstract/engine_api_resource.py", line 153, in create
    response, _, api_key = requestor.request(
  File "/home/lily/hh638/anaconda3/envs/simplification/lib/python3.8/site-packages/openai/api_requestor.py", line 226, in request
    resp, got_stream = self._interpret_response(result, stream)
  File "/home/lily/hh638/anaconda3/envs/simplification/lib/python3.8/site-packages/openai/api_requestor.py", line 620, in _interpret_response
    self._interpret_response_line(
  File "/home/lily/hh638/anaconda3/envs/simplification/lib/python3.8/site-packages/openai/api_requestor.py", line 683, in _interpret_response_line
    raise self.handle_error_response(
openai.error.APIError: Bad gateway. {"error":{"code":502,"message":"Bad gateway.","param":null,"type":"cf_bad_gateway"}} 502 {'error': {'code': 502, 'message': 'Bad gateway.', 'param': None, 'type': 'cf_bad_gateway'}} {'Date': 'Sun, 23 Apr 2023 20:12:05 GMT', 'Content-Type': 'application/json', 'Content-Length': '84', 'Connection': 'keep-alive', 'X-Frame-Options': 'SAMEORIGIN', 'Referrer-Policy': 'same-origin', 'Cache-Control': 'private, max-age=0, no-store, no-cache, must-revalidate, post-check=0, pre-check=0', 'Expires': 'Thu, 01 Jan 1970 00:00:01 GMT', 'Server': 'cloudflare', 'CF-RAY': '7bc8bab5ed740cc1-EWR'}
Using custom data configuration default-3f91e594c1b18797
Reusing dataset json (/home/lily/hh638/.cache/huggingface/datasets/json/default-3f91e594c1b18797/0.0.0/ac0ca5f5289a6cf108e706efcf040422dbbfa8e658dee6a819f20d76bb84d26b)
  0%|          | 0/1 [00:00<?, ?it/s]100%|██████████| 1/1 [00:00<00:00, 32.64it/s]
asset Done
Using custom data configuration default-3e04eaeca4c47c7c
Reusing dataset json (/home/lily/hh638/.cache/huggingface/datasets/json/default-3e04eaeca4c47c7c/0.0.0/ac0ca5f5289a6cf108e706efcf040422dbbfa8e658dee6a819f20d76bb84d26b)
  0%|          | 0/1 [00:00<?, ?it/s]100%|██████████| 1/1 [00:00<00:00, 35.41it/s]
cochrane Done
